Workbook

Sheet Dashboard
A1: Dashboard – Test Progress by Module (Cycle 1)
A3: Module | B3: QA Owner | C3: Test Scenario | D3: Executed | E3: Testing | F3: Not Start | G3: In progress | H3: Passed | I3: Failed | J3: Blocked | K3: Cancelled | L3: TC Total | M3: Pass Rate
A4: EC – Employee Central | B4: Petcharut | C4: =SUM(C5:C7) -> 272 | D4: =H4+I4+J4 -> 17 | E4: =COUNTIF(EC!$M$2:$M$100000,"Ready to test")+COUNTIF(EC!$M$2:$M$100000,"Pending confirm")+COUNTIF(EC!$M$2:$M$100000,"Testing")+COUNTIF(EC!$M$2:$M$100000,"Re-Testing")+COUNTIF(EC!$M$2:$M$100000,"In progress") -> 3 | F4: =L4-G4-H4-I4-J4 -> 157 | G4: =COUNTIF(EC!$M$2:$M$100000,"Pending confirm")+COUNTIF(EC!$M$2:$M$100000,"Testing")+COUNTIF(EC!$M$2:$M$100000,"Re-Testing")+COUNTIF(EC!$M$2:$M$100000,"In progress") -> 3 | H4: =COUNTIF(EC!$M$2:$M$100000,"Passed")+COUNTIF(EC!$M$2:$M$100000,"Re-Test Passed")+COUNTIF(EC!$M$2:$M$100000,"Pass") -> 8 | I4: =COUNTIF(EC!$M$2:$M$100000,"Failed")+COUNTIF(EC!$M$2:$M$100000,"Re-Test Failed") -> 7 | J4: =COUNTIF(EC!$M$2:$M$100000,"Blocked") -> 2 | K4: =COUNTIF(EC!$M$2:$M$100000,"Cancel")+COUNTIF(EC!$M$2:$M$100000,"Cancelled") -> 95 | L4: =COUNTIFS(EC!$C$2:$C$100000,"<>",EC!$M$2:$M$100000,"<>Cancel",EC!$M$2:$M$100000,"<>Cancelled") -> 177 | M4: =IFERROR(H4/L4,"") -> 0.04519774
A5: Hiring | C5: =COUNTIFS(EC!$B$2:$B$100000,"Hiring",EC!$C$2:$C$100000,"<>") -> 150 | D5: =H5+I5+J5 -> 9 | E5: =COUNTIFS(EC!$B$2:$B$100000,"Hiring",EC!$M$2:$M$100000,"Ready to test")+COUNTIFS(EC!$B$2:$B$100000,"Hiring",EC!$M$2:$M$100000,"Pending confirm")+COUNTIFS(EC!$B$2:$B$100000,"Hiring",EC!$M$2:$M$100000,"Testing")+COUNTIFS(EC!$B$2:$B$100000,"Hiring",EC!$M$2:$M$100000,"Re-Testing")+COUNTIFS(EC!$B$2:$B$100000,"Hiring",EC!$M$2:$M$100000,"In progress") -> 1 | F5: =L5-G5-H5-I5-J5 -> 65 | G5: =COUNTIFS(EC!$B$2:$B$100000,"Hiring",EC!$M$2:$M$100000,"Pending confirm")+COUNTIFS(EC!$B$2:$B$100000,"Hiring",EC!$M$2:$M$100000,"Testing")+COUNTIFS(EC!$B$2:$B$100000,"Hiring",EC!$M$2:$M$100000,"Re-Testing")+COUNTIFS(EC!$B$2:$B$100000,"Hiring",EC!$M$2:$M$100000,"In progress") -> 1 | H5: =COUNTIFS(EC!$B$2:$B$100000,"Hiring",EC!$M$2:$M$100000,"Passed")+COUNTIFS(EC!$B$2:$B$100000,"Hiring",EC!$M$2:$M$100000,"Re-Test Passed")+COUNTIFS(EC!$B$2:$B$100000,"Hiring",EC!$M$2:$M$100000,"Pass") -> 1 | I5: =COUNTIFS(EC!$B$2:$B$100000,"Hiring",EC!$M$2:$M$100000,"Failed")+COUNTIFS(EC!$B$2:$B$100000,"Hiring",EC!$M$2:$M$100000,"Re-Test Failed") -> 6 | J5: =COUNTIFS(EC!$B$2:$B$100000,"Hiring",EC!$M$2:$M$100000,"Blocked") -> 2 | K5: =COUNTIFS(EC!$B$2:$B$100000,"Hiring",EC!$M$2:$M$100000,"Cancel")+COUNTIFS(EC!$B$2:$B$100000,"Hiring",EC!$M$2:$M$100000,"Cancelled") -> 75 | L5: =COUNTIFS(EC!$B$2:$B$100000,"Hiring",EC!$C$2:$C$100000,"<>",EC!$M$2:$M$100000,"<>Cancel",EC!$M$2:$M$100000,"<>Cancelled") -> 75 | M5: =IFERROR(H5/L5,"") -> 0.013333333
A6: Probation | C6: =COUNTIFS(EC!$B$2:$B$100000,"Probation",EC!$C$2:$C$100000,"<>") -> 88 | D6: =H6+I6+J6 -> 0 | E6: =COUNTIFS(EC!$B$2:$B$100000,"Probation",EC!$M$2:$M$100000,"Ready to test")+COUNTIFS(EC!$B$2:$B$100000,"Probation",EC!$M$2:$M$100000,"Pending confirm")+COUNTIFS(EC!$B$2:$B$100000,"Probation",EC!$M$2:$M$100000,"Testing")+COUNTIFS(EC!$B$2:$B$100000,"Probation",EC!$M$2:$M$100000,"Re-Testing")+COUNTIFS(EC!$B$2:$B$100000,"Probation",EC!$M$2:$M$100000,"In progress") -> 0 | F6: =L6-G6-H6-I6-J6 -> 88 | G6: =COUNTIFS(EC!$B$2:$B$100000,"Probation",EC!$M$2:$M$100000,"Pending confirm")+COUNTIFS(EC!$B$2:$B$100000,"Probation",EC!$M$2:$M$100000,"Testing")+COUNTIFS(EC!$B$2:$B$100000,"Probation",EC!$M$2:$M$100000,"Re-Testing")+COUNTIFS(EC!$B$2:$B$100000,"Probation",EC!$M$2:$M$100000,"In progress") -> 0 | H6: =COUNTIFS(EC!$B$2:$B$100000,"Probation",EC!$M$2:$M$100000,"Passed")+COUNTIFS(EC!$B$2:$B$100000,"Probation",EC!$M$2:$M$100000,"Re-Test Passed")+COUNTIFS(EC!$B$2:$B$100000,"Probation",EC!$M$2:$M$100000,"Pass") -> 0 | I6: =COUNTIFS(EC!$B$2:$B$100000,"Probation",EC!$M$2:$M$100000,"Failed")+COUNTIFS(EC!$B$2:$B$100000,"Probation",EC!$M$2:$M$100000,"Re-Test Failed") -> 0 | J6: =COUNTIFS(EC!$B$2:$B$100000,"Probation",EC!$M$2:$M$100000,"Blocked") -> 0 | K6: =COUNTIFS(EC!$B$2:$B$100000,"Probation",EC!$M$2:$M$100000,"Cancel")+COUNTIFS(EC!$B$2:$B$100000,"Probation",EC!$M$2:$M$100000,"Cancelled") -> 0 | L6: =COUNTIFS(EC!$B$2:$B$100000,"Probation",EC!$C$2:$C$100000,"<>",EC!$M$2:$M$100000,"<>Cancel",EC!$M$2:$M$100000,"<>Cancelled") -> 88 | M6: =IFERROR(H6/L6,"") -> 0
A7: Consent | C7: =COUNTIFS(EC!$B$2:$B$100000,"Consent",EC!$C$2:$C$100000,"<>") -> 34 | D7: =H7+I7+J7 -> 8 | E7: =COUNTIFS(EC!$B$2:$B$100000,"Consent",EC!$M$2:$M$100000,"Ready to test")+COUNTIFS(EC!$B$2:$B$100000,"Consent",EC!$M$2:$M$100000,"Pending confirm")+COUNTIFS(EC!$B$2:$B$100000,"Consent",EC!$M$2:$M$100000,"Testing")+COUNTIFS(EC!$B$2:$B$100000,"Consent",EC!$M$2:$M$100000,"Re-Testing")+COUNTIFS(EC!$B$2:$B$100000,"Consent",EC!$M$2:$M$100000,"In progress") -> 2 | F7: =L7-G7-H7-I7-J7 -> 4 | G7: =COUNTIFS(EC!$B$2:$B$100000,"Consent",EC!$M$2:$M$100000,"Pending confirm")+COUNTIFS(EC!$B$2:$B$100000,"Consent",EC!$M$2:$M$100000,"Testing")+COUNTIFS(EC!$B$2:$B$100000,"Consent",EC!$M$2:$M$100000,"Re-Testing")+COUNTIFS(EC!$B$2:$B$100000,"Consent",EC!$M$2:$M$100000,"In progress") -> 2 | H7: =COUNTIFS(EC!$B$2:$B$100000,"Consent",EC!$M$2:$M$100000,"Passed")+COUNTIFS(EC!$B$2:$B$100000,"Consent",EC!$M$2:$M$100000,"Re-Test Passed")+COUNTIFS(EC!$B$2:$B$100000,"Consent",EC!$M$2:$M$100000,"Pass") -> 7 | I7: =COUNTIFS(EC!$B$2:$B$100000,"Consent",EC!$M$2:$M$100000,"Failed")+COUNTIFS(EC!$B$2:$B$100000,"Consent",EC!$M$2:$M$100000,"Re-Test Failed") -> 1 | J7: =COUNTIFS(EC!$B$2:$B$100000,"Consent",EC!$M$2:$M$100000,"Blocked") -> 0 | K7: =COUNTIFS(EC!$B$2:$B$100000,"Consent",EC!$M$2:$M$100000,"Cancel")+COUNTIFS(EC!$B$2:$B$100000,"Consent",EC!$M$2:$M$100000,"Cancelled") -> 20 | L7: =COUNTIFS(EC!$B$2:$B$100000,"Consent",EC!$C$2:$C$100000,"<>",EC!$M$2:$M$100000,"<>Cancel",EC!$M$2:$M$100000,"<>Cancelled") -> 14 | M7: =IFERROR(H7/L7,"") -> 0.5
A8: BE – Benefits | B8: Chutiman | C8: =SUM(C9:C10) -> 431 | D8: =H8+I8+J8 -> 195 | E8: =COUNTIF(BE!$M$2:$M$99997,"Ready to test")+COUNTIF(BE!$M$2:$M$99997,"Pending confirm")+COUNTIF(BE!$M$2:$M$99997,"Testing")+COUNTIF(BE!$M$2:$M$99997,"Re-Testing")+COUNTIF(BE!$M$2:$M$99997,"In progress") -> 232 | F8: =L8-G8-H8-I8-J8 -> 232 | G8: =COUNTIF(BE!$M$2:$M$99997,"Pending confirm")+COUNTIF(BE!$M$2:$M$99997,"Testing")+COUNTIF(BE!$M$2:$M$99997,"Re-Testing")+COUNTIF(BE!$M$2:$M$99997,"In progress") -> 4 | H8: =COUNTIF(BE!$M$2:$M$99997,"Passed")+COUNTIF(BE!$M$2:$M$99997,"Re-Test Passed")+COUNTIF(BE!$M$2:$M$99997,"Pass") -> 149 | I8: =COUNTIF(BE!$M$2:$M$99997,"Failed")+COUNTIF(BE!$M$2:$M$99997,"Re-Test Failed") -> 40 | J8: =COUNTIF(BE!$M$2:$M$99997,"Blocked") -> 6 | K8: =COUNTIF(BE!$M$2:$M$99997,"Cancel")+COUNTIF(BE!$M$2:$M$99997,"Cancelled") -> 0 | L8: =COUNTIFS(BE!$D$2:$D$99997,"<>",BE!$M$2:$M$99997,"<>Cancel",BE!$M$2:$M$99997,"<>Cancelled") -> 431 | M8: =IFERROR(H8/L8,"") -> 0.34570766
A9: Benefit Plan | C9: =COUNTIFS(BE!$B$2:$B$99997,"Benefit Plan",BE!$D$2:$D$99997,"<>") -> 222 | D9: =H9+I9+J9 -> 195 | E9: =COUNTIFS(BE!$B$2:$B$99997,"Benefit Plan",BE!$M$2:$M$99997,"Ready to test")+COUNTIFS(BE!$B$2:$B$99997,"Benefit Plan",BE!$M$2:$M$99997,"Pending confirm")+COUNTIFS(BE!$B$2:$B$99997,"Benefit Plan",BE!$M$2:$M$99997,"Testing")+COUNTIFS(BE!$B$2:$B$99997,"Benefit Plan",BE!$M$2:$M$99997,"Re-Testing")+COUNTIFS(BE!$B$2:$B$99997,"Benefit Plan",BE!$M$2:$M$99997,"In progress") -> 23 | F9: =L9-G9-H9-I9-J9 -> 23 | G9: =COUNTIFS(BE!$B$2:$B$99997,"Benefit Plan",BE!$M$2:$M$99997,"Pending confirm")+COUNTIFS(BE!$B$2:$B$99997,"Benefit Plan",BE!$M$2:$M$99997,"Testing")+COUNTIFS(BE!$B$2:$B$99997,"Benefit Plan",BE!$M$2:$M$99997,"Re-Testing")+COUNTIFS(BE!$B$2:$B$99997,"Benefit Plan",BE!$M$2:$M$99997,"In progress") -> 4 | H9: =COUNTIFS(BE!$B$2:$B$99997,"Benefit Plan",BE!$M$2:$M$99997,"Passed")+COUNTIFS(BE!$B$2:$B$99997,"Benefit Plan",BE!$M$2:$M$99997,"Re-Test Passed")+COUNTIFS(BE!$B$2:$B$99997,"Benefit Plan",BE!$M$2:$M$99997,"Pass") -> 149 | I9: =COUNTIFS(BE!$B$2:$B$99997,"Benefit Plan",BE!$M$2:$M$99997,"Failed")+COUNTIFS(BE!$B$2:$B$99997,"Benefit Plan",BE!$M$2:$M$99997,"Re-Test Failed") -> 40 | J9: =COUNTIFS(BE!$B$2:$B$99997,"Benefit Plan",BE!$M$2:$M$99997,"Blocked") -> 6 | K9: =COUNTIFS(BE!$B$2:$B$99997,"Benefit Plan",BE!$M$2:$M$99997,"Cancel")+COUNTIFS(BE!$B$2:$B$99997,"Benefit Plan",BE!$M$2:$M$99997,"Cancelled") -> 0 | L9: =COUNTIFS(BE!$B$2:$B$99997,"Benefit Plan",BE!$D$2:$D$99997,"<>",BE!$M$2:$M$99997,"<>Cancel",BE!$M$2:$M$99997,"<>Cancelled") -> 222 | M9: =IFERROR(H9/L9,"") -> 0.67117117
A10: Benefit Rule | C10: =COUNTIFS(BE!$B$2:$B$99997,"Benefit Rule",BE!$D$2:$D$99997,"<>") -> 209 | D10: =H10+I10+J10 -> 0 | E10: =COUNTIFS(BE!$B$2:$B$99997,"Benefit Rule",BE!$M$2:$M$99997,"Ready to test")+COUNTIFS(BE!$B$2:$B$99997,"Benefit Rule",BE!$M$2:$M$99997,"Pending confirm")+COUNTIFS(BE!$B$2:$B$99997,"Benefit Rule",BE!$M$2:$M$99997,"Testing")+COUNTIFS(BE!$B$2:$B$99997,"Benefit Rule",BE!$M$2:$M$99997,"Re-Testing")+COUNTIFS(BE!$B$2:$B$99997,"Benefit Rule",BE!$M$2:$M$99997,"In progress") -> 209 | F10: =L10-G10-H10-I10-J10 -> 209 | G10: =COUNTIFS(BE!$B$2:$B$99997,"Benefit Rule",BE!$M$2:$M$99997,"Pending confirm")+COUNTIFS(BE!$B$2:$B$99997,"Benefit Rule",BE!$M$2:$M$99997,"Testing")+COUNTIFS(BE!$B$2:$B$99997,"Benefit Rule",BE!$M$2:$M$99997,"Re-Testing")+COUNTIFS(BE!$B$2:$B$99997,"Benefit Rule",BE!$M$2:$M$99997,"In progress") -> 0 | H10: =COUNTIFS(BE!$B$2:$B$99997,"Benefit Rule",BE!$M$2:$M$99997,"Passed")+COUNTIFS(BE!$B$2:$B$99997,"Benefit Rule",BE!$M$2:$M$99997,"Re-Test Passed")+COUNTIFS(BE!$B$2:$B$99997,"Benefit Rule",BE!$M$2:$M$99997,"Pass") -> 0 | I10: =COUNTIFS(BE!$B$2:$B$99997,"Benefit Rule",BE!$M$2:$M$99997,"Failed")+COUNTIFS(BE!$B$2:$B$99997,"Benefit Rule",BE!$M$2:$M$99997,"Re-Test Failed") -> 0 | J10: =COUNTIFS(BE!$B$2:$B$99997,"Benefit Rule",BE!$M$2:$M$99997,"Blocked") -> 0 | K10: =COUNTIFS(BE!$B$2:$B$99997,"Benefit Rule",BE!$M$2:$M$99997,"Cancel")+COUNTIFS(BE!$B$2:$B$99997,"Benefit Rule",BE!$M$2:$M$99997,"Cancelled") -> 0 | L10: =COUNTIFS(BE!$B$2:$B$99997,"Benefit Rule",BE!$D$2:$D$99997,"<>",BE!$M$2:$M$99997,"<>Cancel",BE!$M$2:$M$99997,"<>Cancelled") -> 209 | M10: =IFERROR(H10/L10,"") -> 0
A11: TM – Time Management | B11: Siriya | C11: =SUM(C12:C17) -> 223 | D11: =H11+I11+J11 -> 108 | E11: =COUNTIF(TM!$M$2:$M$100000,"Ready to test")+COUNTIF(TM!$M$2:$M$100000,"Pending confirm")+COUNTIF(TM!$M$2:$M$100000,"Testing")+COUNTIF(TM!$M$2:$M$100000,"Re-Testing")+COUNTIF(TM!$M$2:$M$100000,"In progress") -> 12 | F11: =L11-G11-H11-I11-J11 -> 102 | G11: =SUM(G12:G17) -> 11 | H11: =COUNTIF(TM!$M$2:$M$100000,"Passed")+COUNTIF(TM!$M$2:$M$100000,"Re-Test Passed")+COUNTIF(TM!$M$2:$M$100000,"Pass") -> 17 | I11: =COUNTIF(TM!$M$2:$M$100000,"Failed")+COUNTIF(TM!$M$2:$M$100000,"Re-Test Failed") -> 5 | J11: =COUNTIF(TM!$M$2:$M$100000,"Blocked") -> 86 | K11: =COUNTIF(TM!$M$2:$M$100000,"Cancel")+COUNTIF(TM!$M$2:$M$100000,"Cancelled") -> 2 | L11: =SUM(L12:L17) -> 221 | M11: =IFERROR(H11/L11,"") -> 0.076923077
A12: Web Clocking | C12: =COUNTIFS(TM!$B$2:$B$100000,"Web Clocking") -> 58 | D12: =H12+I12+J12 -> 47 | E12: =COUNTIFS(TM!$B$2:$B$100000,"Web Clocking",TM!$M$2:$M$100000,"Ready to test")+COUNTIFS(TM!$B$2:$B$100000,"Web Clocking",TM!$M$2:$M$100000,"Pending confirm")+COUNTIFS(TM!$B$2:$B$100000,"Web Clocking",TM!$M$2:$M$100000,"Testing")+COUNTIFS(TM!$B$2:$B$100000,"Web Clocking",TM!$M$2:$M$100000,"Re-Testing")+COUNTIFS(TM!$B$2:$B$100000,"Web Clocking",TM!$M$2:$M$100000,"In progress") -> 11 | F12: =L12-G12-H12-I12-J12 -> 0 | G12: =COUNTIFS(TM!$B$2:$B$100000,"Web Clocking",TM!$M$2:$M$100000,"Ready to test")+COUNTIFS(TM!$B$2:$B$100000,"Web Clocking",TM!$M$2:$M$100000,"Pending confirm")+COUNTIFS(TM!$B$2:$B$100000,"Web Clocking",TM!$M$2:$M$100000,"Testing")+COUNTIFS(TM!$B$2:$B$100000,"Web Clocking",TM!$M$2:$M$100000,"Re-Testing")+COUNTIFS(TM!$B$2:$B$100000,"Web Clocking",TM!$M$2:$M$100000,"In progress") -> 11 | H12: =COUNTIFS(TM!$B$2:$B$100000,"Web Clocking",TM!$M$2:$M$100000,"Passed")+COUNTIFS(TM!$B$2:$B$100000,"Web Clocking",TM!$M$2:$M$100000,"Re-Test Passed")+COUNTIFS(TM!$B$2:$B$100000,"Web Clocking",TM!$M$2:$M$100000,"Pass") -> 2 | I12: =COUNTIFS(TM!$B$2:$B$100000,"Web Clocking",TM!$M$2:$M$100000,"Failed")+COUNTIFS(TM!$B$2:$B$100000,"Web Clocking",TM!$M$2:$M$100000,"Re-Test Failed") -> 1 | J12: =COUNTIFS(TM!$B$2:$B$100000,"Web Clocking",TM!$M$2:$M$100000,"Blocked") -> 44 | K12: =COUNTIFS(TM!$B$2:$B$100000,"Web Clocking",TM!$M$2:$M$100000,"Cancel")+COUNTIFS(TM!$B$2:$B$100000,"Web Clocking",TM!$M$2:$M$100000,"Cancelled") -> 0 | L12: =COUNTIFS(TM!$B$2:$B$100000,"Web Clocking",TM!$M$2:$M$100000,"<>Cancel",TM!$M$2:$M$100000,"<>Cancelled") -> 58 | M12: =IFERROR(H12/L12,"") -> 0.034482759
A13: OT Request | C13: =COUNTIFS(TM!$B$2:$B$100000,"OT Request") -> 16 | D13: =H13+I13+J13 -> 0 | E13: =COUNTIFS(TM!$B$2:$B$100000,"OT Request",TM!$M$2:$M$100000,"Ready to test")+COUNTIFS(TM!$B$2:$B$100000,"OT Request",TM!$M$2:$M$100000,"Pending confirm")+COUNTIFS(TM!$B$2:$B$100000,"OT Request",TM!$M$2:$M$100000,"Testing")+COUNTIFS(TM!$B$2:$B$100000,"OT Request",TM!$M$2:$M$100000,"Re-Testing")+COUNTIFS(TM!$B$2:$B$100000,"OT Request",TM!$M$2:$M$100000,"In progress") -> 0 | F13: =L13-G13-H13-I13-J13 -> 16 | G13: =COUNTIFS(TM!$B$2:$B$100000,"OT Request",TM!$M$2:$M$100000,"Pending confirm")+COUNTIFS(TM!$B$2:$B$100000,"OT Request",TM!$M$2:$M$100000,"Testing")+COUNTIFS(TM!$B$2:$B$100000,"OT Request",TM!$M$2:$M$100000,"Re-Testing")+COUNTIFS(TM!$B$2:$B$100000,"OT Request",TM!$M$2:$M$100000,"In progress") -> 0 | H13: =COUNTIFS(TM!$B$2:$B$100000,"OT Request",TM!$M$2:$M$100000,"Passed")+COUNTIFS(TM!$B$2:$B$100000,"OT Request",TM!$M$2:$M$100000,"Re-Test Passed")+COUNTIFS(TM!$B$2:$B$100000,"OT Request",TM!$M$2:$M$100000,"Pass") -> 0 | I13: =COUNTIFS(TM!$B$2:$B$100000,"OT Request",TM!$M$2:$M$100000,"Failed")+COUNTIFS(TM!$B$2:$B$100000,"OT Request",TM!$M$2:$M$100000,"Re-Test Failed") -> 0 | J13: =COUNTIFS(TM!$B$2:$B$100000,"OT Request",TM!$M$2:$M$100000,"Blocked") -> 0 | K13: =COUNTIFS(TM!$B$2:$B$100000,"OT Request",TM!$M$2:$M$100000,"Cancel")+COUNTIFS(TM!$B$2:$B$100000,"OT Request",TM!$M$2:$M$100000,"Cancelled") -> 0 | L13: =COUNTIFS(TM!$B$2:$B$100000,"OT Request",TM!$M$2:$M$100000,"<>Cancel",TM!$M$2:$M$100000,"<>Cancelled") -> 16 | M13: =IFERROR(H13/L13,"") -> 0
A14: Time Correction | C14: =COUNTIFS(TM!$B$2:$B$100000,"Time Correction") -> 11 | D14: =H14+I14+J14 -> 0 | E14: =COUNTIFS(TM!$B$2:$B$100000,"Time Correction",TM!$M$2:$M$100000,"Ready to test")+COUNTIFS(TM!$B$2:$B$100000,"Time Correction",TM!$M$2:$M$100000,"Pending confirm")+COUNTIFS(TM!$B$2:$B$100000,"Time Correction",TM!$M$2:$M$100000,"Testing")+COUNTIFS(TM!$B$2:$B$100000,"Time Correction",TM!$M$2:$M$100000,"Re-Testing")+COUNTIFS(TM!$B$2:$B$100000,"Time Correction",TM!$M$2:$M$100000,"In progress") -> 0 | F14: =L14-G14-H14-I14-J14 -> 11 | G14: =COUNTIFS(TM!$B$2:$B$100000,"Time Correction",TM!$M$2:$M$100000,"Pending confirm")+COUNTIFS(TM!$B$2:$B$100000,"Time Correction",TM!$M$2:$M$100000,"Testing")+COUNTIFS(TM!$B$2:$B$100000,"Time Correction",TM!$M$2:$M$100000,"Re-Testing")+COUNTIFS(TM!$B$2:$B$100000,"Time Correction",TM!$M$2:$M$100000,"In progress") -> 0 | H14: =COUNTIFS(TM!$B$2:$B$100000,"Time Correction",TM!$M$2:$M$100000,"Passed")+COUNTIFS(TM!$B$2:$B$100000,"Time Correction",TM!$M$2:$M$100000,"Re-Test Passed")+COUNTIFS(TM!$B$2:$B$100000,"Time Correction",TM!$M$2:$M$100000,"Pass") -> 0 | I14: =COUNTIFS(TM!$B$2:$B$100000,"Time Correction",TM!$M$2:$M$100000,"Failed")+COUNTIFS(TM!$B$2:$B$100000,"Time Correction",TM!$M$2:$M$100000,"Re-Test Failed") -> 0 | J14: =COUNTIFS(TM!$B$2:$B$100000,"Time Correction",TM!$M$2:$M$100000,"Blocked") -> 0 | K14: =COUNTIFS(TM!$B$2:$B$100000,"Time Correction",TM!$M$2:$M$100000,"Cancel")+COUNTIFS(TM!$B$2:$B$100000,"Time Correction",TM!$M$2:$M$100000,"Cancelled") -> 0 | L14: =COUNTIFS(TM!$B$2:$B$100000,"Time Correction",TM!$M$2:$M$100000,"<>Cancel",TM!$M$2:$M$100000,"<>Cancelled") -> 11 | M14: =IFERROR(H14/L14,"") -> 0
A15: Leave Request | C15: =COUNTIFS(TM!$B$2:$B$100000,"Leave Request") -> 71 | D15: =H15+I15+J15 -> 21 | E15: =COUNTIFS(TM!$B$2:$B$100000,"Leave Request",TM!$M$2:$M$100000,"Ready to test")+COUNTIFS(TM!$B$2:$B$100000,"Leave Request",TM!$M$2:$M$100000,"Pending confirm")+COUNTIFS(TM!$B$2:$B$100000,"Leave Request",TM!$M$2:$M$100000,"Testing")+COUNTIFS(TM!$B$2:$B$100000,"Leave Request",TM!$M$2:$M$100000,"Re-Testing")+COUNTIFS(TM!$B$2:$B$100000,"Leave Request",TM!$M$2:$M$100000,"In progress") -> 1 | F15: =L15-G15-H15-I15-J15 -> 50 | G15: =COUNTIFS(TM!$B$2:$B$100000,"Leave Request",TM!$M$2:$M$100000,"Pending confirm")+COUNTIFS(TM!$B$2:$B$100000,"Leave Request",TM!$M$2:$M$100000,"Testing")+COUNTIFS(TM!$B$2:$B$100000,"Leave Request",TM!$M$2:$M$100000,"Re-Testing")+COUNTIFS(TM!$B$2:$B$100000,"Leave Request",TM!$M$2:$M$100000,"In progress") -> 0 | H15: =COUNTIFS(TM!$B$2:$B$100000,"Leave Request",TM!$M$2:$M$100000,"Passed")+COUNTIFS(TM!$B$2:$B$100000,"Leave Request",TM!$M$2:$M$100000,"Re-Test Passed")+COUNTIFS(TM!$B$2:$B$100000,"Leave Request",TM!$M$2:$M$100000,"Pass") -> 9 | I15: =COUNTIFS(TM!$B$2:$B$100000,"Leave Request",TM!$M$2:$M$100000,"Failed")+COUNTIFS(TM!$B$2:$B$100000,"Leave Request",TM!$M$2:$M$100000,"Re-Test Failed") -> 2 | J15: =COUNTIFS(TM!$B$2:$B$100000,"Leave Request",TM!$M$2:$M$100000,"Blocked") -> 10 | K15: =COUNTIFS(TM!$B$2:$B$100000,"Leave Request",TM!$M$2:$M$100000,"Cancel")+COUNTIFS(TM!$B$2:$B$100000,"Leave Request",TM!$M$2:$M$100000,"Cancelled") -> 0 | L15: =COUNTIFS(TM!$B$2:$B$100000,"Leave Request",TM!$M$2:$M$100000,"<>Cancel",TM!$M$2:$M$100000,"<>Cancelled") -> 71 | M15: =IFERROR(H15/L15,"") -> 0.12676056
A16: Timesheet | C16: =COUNTIFS(TM!$B$2:$B$100000,"Timesheet") -> 55 | D16: =H16+I16+J16 -> 40 | E16: =COUNTIFS(TM!$B$2:$B$100000,"Timesheet",TM!$M$2:$M$100000,"Ready to test")+COUNTIFS(TM!$B$2:$B$100000,"Timesheet",TM!$M$2:$M$100000,"Pending confirm")+COUNTIFS(TM!$B$2:$B$100000,"Timesheet",TM!$M$2:$M$100000,"Testing")+COUNTIFS(TM!$B$2:$B$100000,"Timesheet",TM!$M$2:$M$100000,"Re-Testing")+COUNTIFS(TM!$B$2:$B$100000,"Timesheet",TM!$M$2:$M$100000,"In progress") -> 0 | F16: =L16-G16-H16-I16-J16 -> 13 | G16: =COUNTIFS(TM!$B$2:$B$100000,"Timesheet",TM!$M$2:$M$100000,"Pending confirm")+COUNTIFS(TM!$B$2:$B$100000,"Timesheet",TM!$M$2:$M$100000,"Testing")+COUNTIFS(TM!$B$2:$B$100000,"Timesheet",TM!$M$2:$M$100000,"Re-Testing")+COUNTIFS(TM!$B$2:$B$100000,"Timesheet",TM!$M$2:$M$100000,"In progress") -> 0 | H16: =COUNTIFS(TM!$B$2:$B$100000,"Timesheet",TM!$M$2:$M$100000,"Passed")+COUNTIFS(TM!$B$2:$B$100000,"Timesheet",TM!$M$2:$M$100000,"Re-Test Passed")+COUNTIFS(TM!$B$2:$B$100000,"Timesheet",TM!$M$2:$M$100000,"Pass") -> 6 | I16: =COUNTIFS(TM!$B$2:$B$100000,"Timesheet",TM!$M$2:$M$100000,"Failed")+COUNTIFS(TM!$B$2:$B$100000,"Timesheet",TM!$M$2:$M$100000,"Re-Test Failed") -> 2 | J16: =COUNTIFS(TM!$B$2:$B$100000,"Timesheet",TM!$M$2:$M$100000,"Blocked") -> 32 | K16: =COUNTIFS(TM!$B$2:$B$100000,"Timesheet",TM!$M$2:$M$100000,"Cancel")+COUNTIFS(TM!$B$2:$B$100000,"Timesheet",TM!$M$2:$M$100000,"Cancelled") -> 2 | L16: =COUNTIFS(TM!$B$2:$B$100000,"Timesheet",TM!$M$2:$M$100000,"<>Cancel",TM!$M$2:$M$100000,"<>Cancelled") -> 53 | M16: =IFERROR(H16/L16,"") -> 0.11320755
A17: Cal to PY | C17: =COUNTIFS(TM!$B$2:$B$100000,"Cal to PY") -> 12 | D17: =H17+I17+J17 -> 0 | E17: =COUNTIFS(TM!$B$2:$B$100000,"Cal to PY",TM!$M$2:$M$100000,"Ready to test")+COUNTIFS(TM!$B$2:$B$100000,"Cal to PY",TM!$M$2:$M$100000,"Pending confirm")+COUNTIFS(TM!$B$2:$B$100000,"Cal to PY",TM!$M$2:$M$100000,"Testing")+COUNTIFS(TM!$B$2:$B$100000,"Cal to PY",TM!$M$2:$M$100000,"Re-Testing")+COUNTIFS(TM!$B$2:$B$100000,"Cal to PY",TM!$M$2:$M$100000,"In progress") -> 0 | F17: =L17-G17-H17-I17-J17 -> 12 | G17: =COUNTIFS(TM!$B$2:$B$100000,"Cal to PY",TM!$M$2:$M$100000,"Pending confirm")+COUNTIFS(TM!$B$2:$B$100000,"Cal to PY",TM!$M$2:$M$100000,"Testing")+COUNTIFS(TM!$B$2:$B$100000,"Cal to PY",TM!$M$2:$M$100000,"Re-Testing")+COUNTIFS(TM!$B$2:$B$100000,"Cal to PY",TM!$M$2:$M$100000,"In progress") -> 0 | H17: =COUNTIFS(TM!$B$2:$B$100000,"Cal to PY",TM!$M$2:$M$100000,"Passed")+COUNTIFS(TM!$B$2:$B$100000,"Cal to PY",TM!$M$2:$M$100000,"Re-Test Passed")+COUNTIFS(TM!$B$2:$B$100000,"Cal to PY",TM!$M$2:$M$100000,"Pass") -> 0 | I17: =COUNTIFS(TM!$B$2:$B$100000,"Cal to PY",TM!$M$2:$M$100000,"Failed")+COUNTIFS(TM!$B$2:$B$100000,"Cal to PY",TM!$M$2:$M$100000,"Re-Test Failed") -> 0 | J17: =COUNTIFS(TM!$B$2:$B$100000,"Cal to PY",TM!$M$2:$M$100000,"Blocked") -> 0 | K17: =COUNTIFS(TM!$B$2:$B$100000,"Cal to PY",TM!$M$2:$M$100000,"Cancel")+COUNTIFS(TM!$B$2:$B$100000,"Cal to PY",TM!$M$2:$M$100000,"Cancelled") -> 0 | L17: =COUNTIFS(TM!$B$2:$B$100000,"Cal to PY",TM!$M$2:$M$100000,"<>Cancel",TM!$M$2:$M$100000,"<>Cancelled") -> 12 | M17: =IFERROR(H17/L17,"") -> 0
A18: PY – Payroll | B18: Pongsakorn | C18: =COUNTIFS(PY!$D$3:$D$99991,"<>") -> 360 | D18: =H18+I18+J18 -> 265 | E18: =COUNTIF(PY!$M$3:$M$99998,"Ready to test")+COUNTIF(PY!$M$3:$M$99998,"Pending confirm")+COUNTIF(PY!$M$3:$M$99998,"Testing")+COUNTIF(PY!$M$3:$M$99998,"Re-Testing")+COUNTIF(PY!$M$3:$M$99998,"In progress") -> 0 | F18: =L18-G18-H18-I18-J18 -> 95 | G18: =COUNTIF(PY!$M$3:$M$99998,"Pending confirm")+COUNTIF(PY!$M$3:$M$99998,"Testing")+COUNTIF(PY!$M$3:$M$99998,"Re-Testing")+COUNTIF(PY!$M$3:$M$99998,"In progress") -> 0 | H18: =COUNTIF(PY!$M$3:$M$99998,"Passed")+COUNTIF(PY!$M$3:$M$99998,"Re-Test Passed")+COUNTIF(PY!$M$3:$M$99998,"Pass") -> 141 | I18: =COUNTIF(PY!$M$3:$M$99998,"Failed")+COUNTIF(PY!$M$3:$M$99998,"Re-Test Failed") -> 112 | J18: =COUNTIF(PY!$M$3:$M$99998,"Blocked") -> 12 | K18: =COUNTIF(PY!$M$3:$M$99998,"Cancel")+COUNTIF(PY!$M$3:$M$99998,"Cancelled") -> 0 | L18: =COUNTIFS(PY!$D$3:$D$99991,"<>",PY!$M$3:$M$99991,"<>Cancel",PY!$M$3:$M$99991,"<>Cancelled") -> 360 | M18: =IFERROR(H18/L18,"") -> 0.39166667
A19: Processing | C19: =COUNTIFS(PY!$B$3:$B$99992,"Processing",PY!$D$3:$D$99992,"<>") -> 116 | D19: =H19+I19+J19 -> 23 | E19: =COUNTIFS(PY!$B$3:$B$99998,"Processing",PY!$M$3:$M$99998,"Ready to test")+COUNTIFS(PY!$B$3:$B$99998,"Processing",PY!$M$3:$M$99998,"Pending confirm")+COUNTIFS(PY!$B$3:$B$99998,"Processing",PY!$M$3:$M$99998,"Testing")+COUNTIFS(PY!$B$3:$B$99998,"Processing",PY!$M$3:$M$99998,"Re-Testing")+COUNTIFS(PY!$B$3:$B$99998,"Processing",PY!$M$3:$M$99998,"In progress") -> 0 | F19: =L19-G19-H19-I19-J19 -> 93 | G19: =COUNTIFS(PY!$B$3:$B$99998,"Processing",PY!$M$3:$M$99998,"Pending confirm")+COUNTIFS(PY!$B$3:$B$99998,"Processing",PY!$M$3:$M$99998,"Testing")+COUNTIFS(PY!$B$3:$B$99998,"Processing",PY!$M$3:$M$99998,"Re-Testing")+COUNTIFS(PY!$B$3:$B$99998,"Processing",PY!$M$3:$M$99998,"In progress") -> 0 | H19: =COUNTIFS(PY!$B$3:$B$99998,"Processing",PY!$M$3:$M$99998,"Passed")+COUNTIFS(PY!$B$3:$B$99998,"Processing",PY!$M$3:$M$99998,"Re-Test Passed")+COUNTIFS(PY!$B$3:$B$99998,"Processing",PY!$M$3:$M$99998,"Pass") -> 15 | I19: =COUNTIFS(PY!$B$3:$B$99998,"Processing",PY!$M$3:$M$99998,"Failed")+COUNTIFS(PY!$B$3:$B$99998,"Processing",PY!$M$3:$M$99998,"Re-Test Failed") -> 6 | J19: =COUNTIFS(PY!$B$3:$B$99998,"Processing",PY!$M$3:$M$99998,"Blocked") -> 2 | K19: =COUNTIFS(PY!$B$3:$B$99998,"Processing",PY!$M$3:$M$99998,"Cancel")+COUNTIFS(PY!$B$3:$B$99998,"Processing",PY!$M$3:$M$99998,"Cancelled") -> 0 | L19: =COUNTIFS(PY!$B$3:$B$99992,"Processing",PY!$D$3:$D$99992,"<>",PY!$M$3:$M$99992,"<>Cancel",PY!$M$3:$M$99992,"<>Cancelled") -> 116 | M19: =IFERROR(H19/L19,"") -> 0.12931034
A20: Configuration | C20: =COUNTIFS(PY!$B$3:$B$99992,"Configuration",PY!$D$3:$D$99992,"<>") -> 244 | D20: =H20+I20+J20 -> 242 | E20: =COUNTIFS([1]PY!$B$3:$B$99998,"Configuration",[1]PY!$M$3:$M$99998,"Ready to test")+COUNTIFS([1]PY!$B$3:$B$99998,"Configuration",[1]PY!$M$3:$M$99998,"Pending confirm")+COUNTIFS([1]PY!$B$3:$B$99998,"Configuration",[1]PY!$M$3:$M$99998,"Testing")+COUNTIFS([1]PY!$B$3:$B$99998,"Configuration",[1]PY!$M$3:$M$99998,"Re-Testing")+COUNTIFS([1]PY!$B$3:$B$99998,"Configuration",[1]PY!$M$3:$M$99998,"In progress") -> #VALUE! | F20: =L20-G20-H20-I20-J20 -> 2 | G20: =COUNTIFS(PY!$B$3:$B$99998,"Configuration",PY!$M$3:$M$99998,"Pending confirm")+COUNTIFS(PY!$B$3:$B$99998,"Configuration",PY!$M$3:$M$99998,"Testing")+COUNTIFS(PY!$B$3:$B$99998,"Configuration",PY!$M$3:$M$99998,"Re-Testing")+COUNTIFS(PY!$B$3:$B$99998,"Configuration",PY!$M$3:$M$99998,"In progress") -> 0 | H20: =COUNTIFS(PY!$B$3:$B$99998,"Configuration",PY!$M$3:$M$99998,"Passed")+COUNTIFS(PY!$B$3:$B$99998,"Configuration",PY!$M$3:$M$99998,"Re-Test Passed")+COUNTIFS(PY!$B$3:$B$99998,"Configuration",PY!$M$3:$M$99998,"Pass") -> 126 | I20: =COUNTIFS(PY!$B$3:$B$99998,"Configuration",PY!$M$3:$M$99998,"Failed")+COUNTIFS(PY!$B$3:$B$99998,"Configuration",PY!$M$3:$M$99998,"Re-Test Failed") -> 106 | J20: =COUNTIFS(PY!$B$3:$B$99998,"Configuration",PY!$M$3:$M$99998,"Blocked") -> 10 | K20: =COUNTIFS(PY!$B$3:$B$99998,"Configuration",PY!$M$3:$M$99998,"Cancel")+COUNTIFS(PY!$B$3:$B$99998,"Configuration",PY!$M$3:$M$99998,"Cancelled") -> 0 | L20: =COUNTIFS(PY!$B$3:$B$99992,"Configuration",PY!$D$3:$D$99992,"<>",PY!$M$3:$M$99992,"<>Cancel",PY!$M$3:$M$99992,"<>Cancelled") -> 244 | M20: =IFERROR(H20/L20,"") -> 0.51639344
A21: TOTAL | C21: =C4+C8+C11+C18 -> 1286 | D21: =D4+D8+D11+D18 -> 585 | E21: =E4+E8+E11+E18 -> 247 | F21: =F4+F8+F11+F18 -> 586 | G21: =G4+G8+G11+G18 -> 18 | H21: =H4+H8+H11+H18 -> 315 | I21: =I4+I8+I11+I18 -> 164 | J21: =J4+J8+J11+J18 -> 106 | ... L21: =L4+L8+L11+L18 -> 1189 | M21: =IFERROR(H21/L21,"") -> 0.26492851

Sheet Defects
A1: OPEN DEFECTS / BLOCKERS
A3: Total Open | B3: =COUNTIFS(Blockers!$D$4:$D$103,"<>",Blockers!$I$4:$I$103,"<>Closed",Blockers!$I$4:$I$103,"<>Resolved",Blockers!$I$4:$I$103,"<>Done") -> 5 | C3: Highest | D3: =COUNTIFS(Blockers!$D$4:$D$103,"<>",Blockers!$F$4:$F$103,"Highest",Blockers!$I$4:$I$103,"<>Closed",Blockers!$I$4:$I$103,"<>Resolved",Blockers!$I$4:$I$103,"<>Done") -> 1 | E3: High | F3: =COUNTIFS(Blockers!$D$4:$D$103,"<>",Blockers!$F$4:$F$103,"High",Blockers!$I$4:$I$103,"<>Closed",Blockers!$I$4:$I$103,"<>Resolved",Blockers!$I$4:$I$103,"<>Done") -> 1 | G3: Medium | H3: =COUNTIFS(Blockers!$D$4:$D$103,"<>",Blockers!$F$4:$F$103,"Medium",Blockers!$I$4:$I$103,"<>Closed",Blockers!$I$4:$I$103,"<>Resolved",Blockers!$I$4:$I$103,"<>Done") -> 2 | I3: Low | J3: =COUNTIFS(Blockers!$D$4:$D$103,"<>",Blockers!$F$4:$F$103,"Low",Blockers!$I$4:$I$103,"<>Closed",Blockers!$I$4:$I$103,"<>Resolved",Blockers!$I$4:$I$103,"<>Done") -> 1
A5: # | B5: Module | C5: Bug No. | D5: Date Reported | E5: Issue | K5: Severity | L5: Owner | M5: ETA | N5: Status | O5: Status | P5: Note
A6: 1 | B6: EC | C6: BUG 71875 | D6: 46266 | E6: [EC-Hiring] แก้ไขรายการ Save Draft เดิม แต่ใน DB: transaction_new_hires สร้าง Transaction ใหม่ | K6: 2 - High | L6: Thanakorn Sirikulpan | N6: New | O6: New
A7: 2 | B7: EC | C7: BUG 71873 | D7: 46266 | E7: [EC-Hiring] Field 'Position' แสดงค่าใน dropdownlist ซ้ำ | K7: 3 - Medium | L7: Thanakorn Sirikulpan | N7: New
A8: 3 | B8: EC | C8: BUG 71887 | D8: 46266 | E8: [EC-Hiring] กดปุ่ม 'View Details' New employee หลัง Submit ระบบแสดงหน้าจอ '404 - ไม่พบหน้าที่ค้นหา' | K8: 2 - High | L8: Thanakorn Sirikulpan | N8: New
A9: 4 | B9: EC | C9: BUG 71888 | D9: 46266 | E9: [EC-Hiring] หลัง Submit รายการ Save Draft สำเร็จ ระบบไม่เคลียร์รายการเดิมออกจาก Tab Draft Form | K9: 2 - High | L9: Thanakorn Sirikulpan | N9: New
A10: 5 | B10: EC | C10: BUG 71851 | D10: 46266 | E10: [EC-Consent] กดปุ่ม Decline แล้วระบบ redirects กลับมาที่ link Env. Dev | K10: 3 - Medium | L10: Thanakorn Sirikulpan | N10: New
A11: 6 | B11: BE | C11: BUG 70609 | D11: 46266 | E11: [BE-Plan] Unable to save plan when entering more than 50 characters | K11: 3 - Medium | L11: Panupong (Outsource) Jaengaks | M11: 46269 | N11: New
A12: 7 | B12: BE | C12: BUG 70636 | D12: 46266 | E12: [BE-Plan] Benefit Name filter field too narrow when selecting long name | K12: 4 - Low | L12: Panupong (Outsource) Jaengaks | M12: 46276 | N12: New
A13: 8 | B13: BE | C13: BUG 70659 | D13: 46266 | E13: [BE-Plan] Company list is inconsistent with the selected Country | K13: 3 - Medium | L13: Panupong (Outsource) Jaengaks | M13: 46269 | N13: New
A14: 9 | B14: BE | C14: BUG 70658 | D14: 46266 | E14: [BE-Plan] Company dropdown does not show all list of Company | K14: 3 - Medium | L14: Panupong (Outsource) Jaengaks | M14: 46269 | N14: New
A15: 10 | B15: BE | C15: BUG 70675 | D15: 46266 | E15: [BE-Plan] Company dropdown not sorted by Company Name | K15: 4 - Low | L15: Panupong (Outsource) Jaengaks | M15: 46276 | N15: New
A16: 11 | B16: BE | C16: BUG 70676 | D16: 46266 | E16: [BE-Plan] Company field not display error message "This field is required" | K16: 4 - Low | L16: Panupong (Outsource) Jaengaks | M16: 46276 | N16: New
A17: 12 | B17: BE | C17: BUG 70758 | D17: 46266 | E17: [BE-Plan] Effective Start Date field not display error message "Effective start date must not be greater than effective end date." | K17: 4 - Low | L17: Panupong (Outsource) Jaengaks | M17: 46276 | N17: New
A18: 13 | B18: BE | C18: BUG 70787 | D18: 46266 | E18: [BE-Plan] Eligible Claim Date field is not optional | K18: 3 - Medium | L18: Panupong (Outsource) Jaengaks | M18: 46269 | N18: New
A19: 14 | B19: BE | C19: BUG 70798 | D19: 46266 | E19: [BE-Plan] Eligible Claim Date field not display error message "Eligible Claim date can be at most 365 days." | K19: 4 - Low | L19: Panupong (Outsource) Jaengaks | M19: 46276 | N19: New
A20: 15 | B20: BE | C20: BUG 70813 | D20: 46266 | E20: [BE-Plan] Cannot recreate a deleted Benefit Plan ID | K20: 3 - Medium | L20: Panupong (Outsource) Jaengaks | M20: 46269 | N20: New
A21: 16 | B21: BE | C21: BUG 70814 | D21: 46266 | E21: [BE-Plan] Eligible Claim Date field not display error message "Enter number greater than 0" | K21: 3 - Medium | L21: Panupong (Outsource) Jaengaks | M21: 46269 | N21: New
A22: 17 | B22: BE | C22: BUG 70829 | D22: 46266 | E22: [BE-Plan] Make Correction history is displayed under incorrect Effective Date | K22: 1 - Critical | L22: Panupong (Outsource) Jaengaks | M22: 46269 | N22: New | P22: Block PL_08_29
A23: 18 | B23: BE | C23: BUG 70830 | D23: 46266 | E23: [BE-Plan] Insert calendar allows users to select past dates | K23: 3 - Medium | L23: Panupong (Outsource) Jaengaks | M23: 46269 | N23: New
A24: 19 | B24: BE | C24: BUG 70764 | D24: 46266 | E24: [BE-Plan] Benefit Name does not display an error message when entering spaces only | K24: 4 - Low | L24: Panupong (Outsource) Jaengaks | M24: 46276 | N24: New
A25: 20 | B25: BE | C25: BUG 70831 | D25: 46266 | E25: [BE-Plan] Insert Calendar is not fully displayed | K25: 4 - Low | L25: Panupong (Outsource) Jaengaks | M25: 46276 | N25: New
A26: 21 | B26: BE | C26: BUG 71147 | D26: 46266 | E26: [BE-Plan] Benefit Name field does not support all required special characters | K26: 4 - Low | L26: Panupong (Outsource) Jaengaks | M26: 46276 | N26: New
A27: 22 | B27: BE | C27: BUG 71144 | D27: 46266 | E27: [BE-Plan] Plan ID field does not support all required special characters | K27: 4 - Low | L27: Panupong (Outsource) Jaengaks | M27: 46276 | N27: New
A28: 23 | B28: BE | C28: BUG 71164 | D28: 46266 | E28: [BE-Plan] History displays incorrect status | K28: 1 - Critical | L28: Panupong (Outsource) Jaengaks | M28: 46269 | N28: New
A29: 24 | B29: BE | C29: BUG 71210 | D29: 46266 | E29: [BE-Plan] History displays only Company Code instead of Company Name (Code) for Make Correction and Insert | K29: 4 - Low | L29: Panupong (Outsource) Jaengaks | M29: 46276 | N29: New
A30: 25 | B30: BE | C30: BUG 71440 | D30: 46266 | E30: [BE-Plan] Insert Date can be selected earlier than original Effective Start Date | K30: 3 - Medium | L30: Panupong (Outsource) Jaengaks | M30: 46269 | N30: New
A31: 26 | B31: BE | C31: BUG 71448 | D31: 46266 | E31: [BE-Plan] History displays incorrect action for multiple inserts on the same Effective Start Date | K31: 3 - Medium | L31: Panupong (Outsource) Jaengaks | M31: 46269 | N31: New
A32: 27 | B32: BE | C32: BUG 71453 | D32: 46266 | E32: [BE-Plan] Allow insert with duplicate data | K32: 3 - Medium | L32: Panupong (Outsource) Jaengaks | M32: 46269 | N32: New
A33: 28 | B33: BE | C33: BUG 71727 | D33: 46266 | E33: [BE-Plan] Effective Start/End Date allows invalid date format and year exceeding 4 digits | K33: 4 - Low | L33: Panupong (Outsource) Jaengaks | M33: 46276 | N33: New
A34: 29 | B34: TM | C34: BUG 71868 | D34: 46266 | E34: [TM - Web clock] กดปุ่ม clock in/out ไม่ได้ | K34: 2 - High | L34: Sorawich (Outsource) Tantijitjaru | N34: New
A35: 30 | B35: TM | C35: BUG 71890 | D35: 46266 | E35: [TM - Leave] นามสกุลไม่ตรงกัน | K35: 4 - Low | L35: Sorawich (Outsource) Tantijitjaru | N35: New
A36: 31 | B36: TM | C36: BUG 71891 | D36: 46266 | E36: [TM - Leave] ไฟล์ที่อัพโหลดไปเป็นภาษาอ่านไม่ออก | K36: 4 - Low | L36: Sorawich (Outsource) Tantijitjaru | N36: New
A37: 32 | B37: TM | C37: BUG 71893 | D37: 46266 | E37: [TM - Leave] ลาซ้ำวันเดิมที่เคยลาแต่ต่างเวลากัน | K37: 3 - Medium | L37: Sorawich (Outsource) Tantijitjaru | N37: New
A38: 33 | B38: BE | C38: BUG 71907 | D38: 46266 | E38: [BE-Plan] Wording in Download Sample CSV file do not match specification | K38: 4 - Low | L38: Supawit (Outsource) Janngam | M38: 46276 | N38: New
A39: 34 | B39: BE | C39: BUG 71910 | D39: 46266 | E39: [BE-Plan] Column sequence in Validate & Preview table does not match specification | K39: 4 - Low | L39: Supawit (Outsource) Janngam | M39: 46276 | N39: New
A40: 35 | B40: BE | C40: BUG 71912 | D40: 46266 | E40: [BE-Plan] Validate & Preview displays incorrect Special Claim Condition and Condition values | K40: 3 - Medium | L40: Supawit (Outsource) Janngam | M40: 46269 | N40: New
A41: 36 | B41: BE | C41: BUG 71913 | D41: 46266 | E41: [BE-Plan] Rows per page in Validate & Preview table does not display the selected number of rows | K41: 4 - Low | L41: Supawit (Outsource) Janngam | M41: 46276 | N41: New
A42: 37 | B42: EC | C42: BUG 71932 | D42: 46062 | E42: [EC] Event Reason Dropdown Shows Incorrect Options | K42: 3 - Medium | L42: Thanakorn Sirikulpan | N42: New
...

Sheet Board Track
A1: Dashboard – Test Progress by Module
A2: Module | B2: QA Owner | C2: Total Case | D2: Pending deploy | E2: Pending confirm | F2: Ready to test | G2: Testing | H2: Passed | I2: Failed | J2: Blocked | K2: Re-Testing | L2: Re-Test Passed | M2: Re-Test Failed | N2: Total Progress | O2: %Progress | P2: %Passed
A3: EC – Employee Central | B3: Petcharut | C3: 250 | D3: =COUNTIF(EC!$M:$M,"Pending deploy") -> 0 | E3: =COUNTIF(EC!$M:$M,"Pending confirm") -> 0 | F3: =COUNTIF(EC!$M:$M,"Ready to test") -> 0 | G3: =COUNTIF(EC!$M:$M,"Testing") -> 3 | H3: =COUNTIF(EC!$M:$M,"Passed") -> 8 | I3: =COUNTIF(EC!$M:$M,"Failed") -> 7 | J3: =COUNTIF(EC!$M:$M,"Blocked") -> 2 | K3: =COUNTIF(EC!$M:$M,"Re-Testing") -> 0 | L3: =COUNTIF(EC!$M:$M,"Re-Test Passed") -> 0 | M3: =COUNTIF(EC!$M:$M,"Re-Test Failed") -> 0 | N3: =SUM(G3:M3) -> 20 | O3: =SUM(G3:M3)/C3 -> 0.08
A4: BE – Benefits | B4: Chutiman | C4: =SUM(D4:M4) -> 431 | D4: =COUNTIF(BE!$M:$M,"Pending deploy") -> 4 | E4: =COUNTIF(BE!$M:$M,"Pending confirm") -> 4 | F4: =COUNTIF(BE!$M:$M,"Ready to test") -> 228 | G4: =COUNTIF(BE!$M:$M,"Testing") -> 0 | H4: =COUNTIF(BE!$M:$M,"Passed") -> 139 | I4: =COUNTIF(BE!$M:$M,"Failed") -> 40 | J4: =COUNTIF(BE!$M:$M,"Blocked") -> 6 | K4: =COUNTIF(BE!$M:$M,"Re-Testing") -> 0 | L4: =COUNTIF(BE!$M:$M,"Re-Test Passed") -> 10 | M4: =COUNTIF(BE!$M:$M,"Re-Test Failed") -> 0 | N4: =SUM(G4:M4) -> 195 | O4: =SUM(G4:M4)/C4 -> 0.45243619 | P4: =SUM(H4,L4)/C4 -> 0.34570766
A5: TM – Time Management | B5: Siriya Hacha
A6: PY – Payroll | B6: Pongsakorn
A7: TOTAL

Sheet EC
A1: No | B1: Category | C1: Scenario ID | D1: Test Scenario | E1: Test Case ID | F1: Positive/Negative | G1: Priority | H1: Test Case | I1: Test Data | J1: Menu | K1: Test Script / Steps | L1: Expected Output | M1: Test Status | N1: Test Date | O1: Test by | P1: Bug ticket | Q1: Note | R1: Actual Result Image
A2: 1 | B2: Hiring | C2: E2E-01 | D2: Hiring | Keyin - Success | New Hire | Hire Date = Start of Month | Age < 60 | Male | TH | A - Permanent | E2: HIR-EC-001 | F2: Positive | G2: High | H2: ตรวจสอบการจ้างพนักงานใหม่แบบ Key-in สำเร็จ กรณีวันเริ่มงานต้นเดือน อายุ < 60 ปี สัญชาติไทย และเป็นพนักงานประจำ | I2: - Entry Route = Keyin เงื่อนไขของเคสนี้ - Event Reason = New Hire - Hire Date = 01 Sep 2027 - Date of Birth = Age < 60 - Gender = Male - Nationality = Thai - Province = กรุงเทพมหานคร - District = เลือกเขตที่อยู่ในกรุงเทพมหานคร - Sub-District = เลือกแขวงที่อยู่ใน District ที่เลือก - Postal Code = ตาม Sub-District ที่เลือก - Employee Group = A - Permanent - DVT Project = null - Special benefit group flag = No ค่าที่ต้องคีย์ ชุดข้อมูลจากถัง SIT ตรวจสอบเมื่อ 28 ส.ค. 2026 ชุดข้อมูล TD-01 - Business Group = CRC - Business Unit = CDG (10000075) Policy Profile = CDS - Company = C001 - Position = 40106337 Job Code = MKB12.12 - Department = 30042174 Branch = T153_1733 SSO Location = T153 - Division = 20000079 Cost Center = C00132653 Work Location = 50000127 - Work Schedule = D05H0830 Holiday Calendar = 01 - Personnel Grade (PG) = 10 Employee Sub Group ที่ต้องคีย์ = 10 - ตารางกำหนด Time Status = 01 O.T. Flag = yes สิทธิ์ลาพักผ่อนปีแรก = 6 วัน เงื่อนไขเฉพาะของเคสนี้ - Business Unit = CDG (10000075) Policy Profile = CDS ใช้แทน CDS ที่เคยระบุ ดู CF-SIT-19 - Employee Group = A - Permanent Employee Sub Group = 10 - รายละเอียดเต็มดูชีท Hiring Test Data หมายเหตุ - ดราฟต์เดิมระบุ Department = 30001142 ใช้ 30042174 ตามชุดข้อมูลจริงในถัง SIT - ดราฟต์เดิมระบุ Business Unit = CDS ใช้ CDG / CDG ตามชุดข้อมูลจริงในถัง SIT CDS ปิดใช้งานตั้งแต่ 1 ต.ค. 2024 ตามไฟล์ FO และไม่มี Position ในถัง SIT - ดราฟต์เดิมระบุ Employee Sub Group = 07 ใช้ 10 ตามชุดข้อมูลจริงในถัง SIT - ดราฟต์เดิมระบุ Work Schedule = D05H0800_01 ใช้ D05H0830 ตามชุดข้อมูลจริงในถัง SIT | J2: EC > Hire & Onboard (New Hire) | K2: 1. Login ด้วย <HR_ADMIN_ACCOUNT> - ไปที่ EC > New Hire (Manual Key-in) 2. กรอกข้อมูล Identity ตาม Test Data - กรอก Salutation, First Name / Last Name (TH และ EN), Date of Birth, National ID / Tax ID, Hire Date และ Event Reason 3. กรอกและตรวจสอบ Home Address - เลือก Province = กรุงเทพมหานคร และตรวจสอบรายการ District - เลือก District และตรวจสอบรายการ Sub-District - เลือก Sub-District และตรวจสอบ Postal Code - เปลี่ยน Province และตรวจสอบว่า District / Sub-District / Postal Code เดิมถูกเคลียร์ - เลือก Province / District ใหม่ - เปลี่ยน District โดยคง Province เดิม และตรวจสอบว่า Sub-District / Postal Code เดิมถูกเคลียร์ - เลือก Address ที่ถูกต้องให้ครบถ้วน 4. กรอกข้อมูล Position & Organization - เลือก Department / Position ตาม Test Data - ตรวจสอบค่าที่ระบบดึงจาก Department - ตรวจสอบค่าที่ระบบดึงจาก Position - ตรวจสอบ Minimum / Maximum Job Grade ที่ได้จาก Job Code - ตรวจสอบว่า Job Grade อยู่ในช่วงที่กำหนด - ตรวจสอบ Payroll Frequency ที่ได้จาก Pay Group 5. ตรวจสอบ Time Management Status และ O.T. Flag - ตรวจสอบว่าทั้งสองฟิลด์เป็น Read-only - ตรวจสอบค่าที่ระบบ Auto-Derive เทียบกับ Rule Table ตาม Business Unit / Employee Group / Employee Subgroup 6. กรอก Compensation Information และ Payment Information ให้ครบถ้วน 7. กด Submit เพื่อสร้างพนักงานใหม่ 8. ตรวจสอบ Employee Profile ใน EC - ค้นหาด้วย Employee ID - ตรวจสอบ Employee ID / Status / Hire Date / Event Reason / Employee Group / Employee Subgroup - ตรวจสอบ Home Address - ตรวจสอบ Probation Information - ตรวจสอบ Time Management Status / O.T. Flag - ตรวจสอบค่าที่ระบบดึงจาก Master/ทะเบียน | L2: EC - ระบบสร้าง Employee ID เป็นตัวเลข 8 หลัก โดยหลักแรกเป็น 2 - Employee Status = Active - Hire Date = Today ตามค่าที่กรอก - Event Reason = New Hire - Employee Group = A - Permanent - ระบบบันทึกและส่งต่อ Employee Sub Group เป็นรหัสสองหลักตามค่าที่คีย์ในชุดข้อมูล ไม่ตัดศูนย์นำหน้า เช่น 07 ต้องไม่ถูกเก็บเป็น 7 (Q&A ข้อ 23) - ระบบกรอง District ตาม Province ที่เลือก - ระบบกรอง Sub-District ตาม District ที่เลือก - เมื่อเลือก Sub-District ระบบแสดง Postal Code อัตโนมัติ - เมื่อเปลี่ยน Province ระบบเคลียร์ District / Sub-District / Postal Code เดิม - เมื่อเปลี่ยน District ระบบเคลียร์ Sub-District / Postal Code เดิม - ระบบบันทึก Home Address ตามข้อมูลที่ระบุ - Probation Exemption = No - ระบบเริ่มนับ Probation Day 1 ที่ Hire Date - ระบบ Auto-Derive Time Management Status = 01 - Clocking และ O.T. Flag = Yes ตาม Rule Table - Time Management Status และ O.T. Flag เป็น Read-only และ HR ไม่สามารถแก้ไขเองได้ - ระบบดึงข้อมูลจาก Department ได้แก่ Cost Center / SSO Location / Work Location / Store/Branch Location / Policy Profile / Holiday Calendar / Division - ระบบดึงข้อมูลจาก Position ได้แก่ Company / Job Code / Employee Group / Employee Subgroup / Work Schedule - ระบบดึง Minimum / Maximum Job Grade จาก Job Code และ Job Grade ต้องอยู่ในช่วงที่กำหนด - ระบบดึง Payroll Frequency จาก Pay Group - Probationary Period End Date = ? CF-HIR-08 OQ-HIR-50 - สูตร/เงื่อนไข Rule Table = ? OQ-HIR-13 จุดที่ยังไม่มีคำตอบในเคสนี้ ให้รันจริงแล้วบันทึกค่าที่ระบบแสดงลงช่อง Actual Result Image และช่อง Note เพื่อใช้เป็นคำตอบ แล้วส่งให้ BA หรือ SA ยืนยัน หมายเลขคำถามที่ต้องเก็บคำตอบระหว่างรัน CF-HIR-08, OQ-HIR-50, OQ-HIR-13 | M2: Failed | N2: 46267 | O2: QA-Thitiya | P2: #71932 #71983 #72009 #72003 #72011 #72016 #72020 #72038 #72046 #72051 | Q2: ตัดจากเคส E2E-01 ไฟล์ HR_SIT_E2E_V.0.1 (28).xlsx ชีท E2E All module โมดูลที่เคสเต็มเกี่ยวข้อง EC / BE / TM / PY / Notification ยกไปรอบเชื่อมโมดูล ผลที่คาดหวังฝั่ง Notification / TM / Menu Clock in/out / Menu OT Request / Menu Timesheet / BE / PY / ผลข้ามโมดูล ตรวจหลัง Submit สำเร็จแล้ว ยกไปรอบเชื่อมโมดูล ขั้นตอน ตรวจสอบ Notification หลังสร้างพนักงานใหม่ / ตรวจสอบข้อมูลใน BE / TM / PY เคสนี้มีจุดที่ยังไม่มีคำตอบ 3 จุด ไม่ต้องรอคำตอบก่อนรัน ให้รันเก็บค่าที่ระบบแสดงจริงแล้วแจ้ง BA หรือ SA ยืนยันหลังรัน
A3: 2 | B3: Hiring | C3: E2E-02 | D3: Hiring | Keyin - Success | New Hire | Hire Date = Mid Month | Age > 60 | Female | TH | A - Permanent | Save Draft & Submit | E3: HIR-EC-002 | F3: Positive | G3: High | H3: ตรวจสอบการจ้างพนักงานใหม่แบบ Key-in สำเร็จ กรณีวันเริ่มงานกลางเดือน อายุ > 60 ปี เพศหญิง สัญชาติไทย พนักงานประจำ และบันทึกร่างก่อน Submit | I3: - Entry Route = Keyin เงื่อนไขของเคสนี้ - Event Reason = New hire - Hire Date = 15 Sep 2027 - Date of Birth = Age > 60 - Gender = Female - Nationality = Thai - Employee Group = A - Permanent - DVT Project = null - Hire date = 15 Sep 2027 - Special benefit group flag = No - Branch code = TA57_1001 ค่าที่ต้องคีย์ ชุดข้อมูลจากถัง SIT ตรวจสอบเมื่อ 28 ส.ค. 2026 ชุดข้อมูล TD-01 - Business Group = CRC - Business Unit = CDG (10000075) Policy Profile = CDS - Company = C001 - Position = 40106337 Job Code = MKB12.12 - Department = 30042174 Branch = T153_1733 SSO Location = T153 - Division = 20000079 Cost Center = C00132653 Work Location = 50000127 - Work Schedule = D05H0830 Holiday Calendar = 01 - Personnel Grade (PG) = 10 Employee Sub Group ที่ต้องคีย์ = 10 - ตารางกำหนด Time Status = 01 O.T. Flag = yes สิทธิ์ลาพักผ่อนปีแรก = 6 วัน เงื่อนไขเฉพาะของเคสนี้ - Work Schedule = D05H0830 แก้จากเดิมที่ระบุ D05H0800_02 ซึ่งไม่มีในตาราง ดู CF-SIT-11 - Branch code = T153_1733 แก้จากเดิมที่ระบุ TA57_1001 ซึ่งอยู่นอกขอบเขต ดู CF-SIT-10 - รายละเอียดเต็มดูชีท Hiring Test Data หมายเหตุ - ดราฟต์เดิมระบุ Business Unit = CDS ใช้ CDG ตามชุดข้อมูลจริงในถัง SIT CDS ปิดใช้งานตั้งแต่ 1 ต.ค. 2024 ตามไฟล์ FO และไม่มี Position ในถัง SIT - ดราฟต์เดิมระบุ Holiday Calendar = 02 ใช้ 01 / 01 ตามชุดข้อมูลจริงในถัง SIT - ดราฟต์เดิมระบุ Work Schedule = D05H0800_02 ใช้ D05H0830 / D05H0830 ตามชุดข้อมูลจริงในถัง SIT | J3: EC > Hire & Onboard (New Hire) | K3: 1. Login ด้วย <HR_ADMIN_ACCOUNT> - ไปที่ EC > New Hire (Manual Key-in) 2. กรอกข้อมูล New Hire ตาม Test Data - กรอกข้อมูล Identity ตามข้อมูลที่กำหนด - กำหนด Employee Group = A - Permanent - กรอกข้อมูลบางส่วนให้เพียงพอสำหรับ Save Draft โดยยังไม่ต้องกรอกข้อมูลทั้งหมดให้ครบ 3. กด Save Draft ก่อน Submit - ออกจากรายการ New Hire หลังบันทึกร่างสำเร็จ - ตรวจสอบว่ายังไม่มี Employee ID ถูกสร้าง 4. กลับมาเปิด Draft เดิม - ตรวจสอบข้อมูลที่กรอกไว้ก่อน Save Draft - ตรวจสอบว่าค่าเดิมยังอยู่ครบ - กรอกข้อมูล Mandatory ที่เหลือให้ครบถ้วนเพื่อให้สามารถ Submit ได้ 5. กด Submit เพื่อสร้างพนักงานใหม่ 6. ตรวจสอบ Employee Profile ใน EC - ค้นหาพนักงานที่สร้างใหม่ด้วย Employee ID - ตรวจสอบ Hire Date / Date of Birth / Employee Group - ตรวจสอบว่าพนักงานมี Age > 60 ณ Hire Date - ตรวจสอบว่ารายการ Draft ที่ Submit สำเร็จแล้วไม่ค้างอยู่ในรายการ Draft | L3: EC - ระบบบันทึกใบจ้างที่ยังกรอกไม่ครบเป็น Draft ได้สำเร็จ - ระบบเปิด Draft เดิมกลับมาทำต่อได้ และค่าที่กรอกไว้ก่อนหน้ายังอยู่ครบ - ระบบไม่สร้าง Employee ID จากการ Save Draft - ระบบสร้างพนักงานหลัง Submit สำเร็จ - Hire Date = Today (กลางปี) - Employee Group = A - Permanent - ระบบสร้างพนักงาน Age > 60 ได้ โดยไม่มีการ Block ที่ EC - ใบร่างที่ Submit สำเร็จแล้วหายจากรายการ Draft เพื่อป้องกันการนำรายการเดิมกลับมาทำซ้ำ - สถานะของใบร่าง = DRAFT โดยคำที่ระบบเก็บจริง = ? OQ-HIR-91 - สถานะของใบร่างหลัง Submit = COMPLETED โดยคำที่ระบบเก็บจริง = ? OQ-HIR-91 - ระบบอนุญาตให้ Save Draft เมื่อกรอกชื่อและนามสกุลแล้ว (Q&A ข้อ 28) จุดที่ยังไม่มีคำตอบในเคสนี้ ให้รันจริงแล้วบันทึกค่าที่ระบบแสดงลงช่อง Actual Result Image และช่อง Note เพื่อใช้เป็นคำตอบ แล้วส่งให้ BA หรือ SA ยืนยัน หมายเลขคำถามที่ต้องเก็บคำตอบระหว่างรัน OQ-HIR-91 | M3: Failed | N3: 46266 | O3: QA-Wannaphon | P3: #71875 #71887 | Q3: ตัดจากเคส E2E-02 ไฟล์ HR_SIT_E2E_V.0.1 (28).xlsx ชีท E2E All module โมดูลที่เคสเต็มเกี่ยวข้อง EC / BE / TM / PY / Notification ยกไปรอบเชื่อมโมดูล ผลที่คาดหวังฝั่ง Notification / TM / Menu Clock in/out / Menu OT Request / Menu Timesheet / BE / PY ยกไปรอบเชื่อมโมดูล ขั้นตอน ตรวจสอบ Notification หลังสร้างพนักงานใหม่ / ตรวจสอบข้อมูลใน BE / TM / PY หลัง Submit สำเร็จ เคสนี้มีจุดที่ยังไม่มีคำตอบ 1 จุด ไม่ต้องรอคำตอบก่อนรัน ให้รันเก็บค่าที่ระบบแสดงจริงแล้วแจ้ง BA หรือ SA ยืนยันหลังรัน
A4: 3 | B4: Hiring | C4: E2E-03 | D4: Hiring | Keyin - Success | New Hire | Hire Date > Today | Age < 60 | Female | TH | Special Benefit Group = Yes | A - Permanent | E4: HIR-EC-003 | F4: Positive | G4: High | H4: ตรวจสอบการจ้างพนักงานใหม่แบบ Key-in สำเร็จ กรณีวันเริ่มงานในอนาคต อายุ < 60 ปี เพศหญิง สัญชาติไทย พนักงานประจำ และอยู่ใน Special Benefit Group | I4: - Entry Route = Keyin เงื่อนไขของเคสนี้ - Event Reason = New hire - Hire Date = 01 Jan 2027 - Date of Birth = Age < 60 - Gender = Female - Nationality = Thai - Special Benefit Group = Yes - Employee Group = A - Permanent - Copy Address from Employee = Yes / No - Country / Province / District / Sub-District / Postal Code = ใช้สำหรับตรวจ Required เมื่อเลือก No - Building / Floor / Village / Moo / Lane = ใช้สำหรับตรวจ Optional Field - DVT Project = null - Employee group = A - permanent - Special benefit group flag = Yes ค่าที่ต้องคีย์ ชุดข้อมูลจากถัง SIT ตรวจสอบเมื่อ 28 ส.ค. 2026 ชุดข้อมูล TD-01 - Business Group = CRC - Business Unit = CDG (10000075) Policy Profile = CDS - Company = C001 - Position = 40106337 Job Code = MKB12.12 - Department = 30042174 Branch = T153_1733 SSO Location = T153 - Division = 20000079 Cost Center = C00132653 Work Location = 50000127 - Work Schedule = D05H0830 Holiday Calendar = 01 - Personnel Grade (PG) = 10 Employee Sub Group ที่ต้องคีย์ = 10 - ตารางกำหนด Time Status = 01 O.T. Flag = yes สิทธิ์ลาพักผ่อนปีแรก = 6 วัน เงื่อนไขเฉพาะของเคสนี้ - Special Benefit Group = Yes - รายละเอียดเต็มดูชีท Hiring Test Data หมายเหตุ - ดราฟต์เดิมระบุ Business Unit = CDS ใช้ CDG ตามชุดข้อมูลจริงในถัง SIT CDS ปิดใช้งานตั้งแต่ 1 ต.ค. 2024 ตามไฟล์ FO และไม่มี Position ในถัง SIT | J4: EC > Hire & Onboard (New Hire) | K4: 1. Login ด้วย <HR_ADMIN_ACCOUNT> - ไปที่ EC > New Hire (Manual Key-in) 2. กรอกข้อมูล Identity ตาม Test Data - กำหนด Hire Date > Today - กรอกข้อมูลบุคคลตาม Test Data 3. กรอกข้อมูล Dependent / Emergency Contact - เพิ่ม Dependent จำนวน 1 คน - เลือก Copy Address from Employee = Yes และตรวจสอบข้อมูล Address / ข้อความ “The address will be copied from the employee.” - เปลี่ยนเป็น Copy Address from Employee = No - ตรวจสอบว่า Country / Province / District / Sub-District / Postal Code เป็น Required - ตรวจสอบว่า Building / Floor / Village / Moo / Lane แสดงแต่ไม่เป็น Required - ทำซ้ำเงื่อนไขเดียวกันสำหรับ Emergency Contact 4. กรอกข้อมูลการจ้างงานที่จำเป็น - กำหนด Special Benefit Group = Yes - กำหนด Employee Group = A - Permanent - กรอกข้อมูล Mandatory อื่นให้ครบถ้วนเพื่อให้สามารถ Submit ได้ 5. กด Submit เพื่อสร้างพนักงานใหม่ 6. ตรวจสอบ Employee Profile ใน EC - ค้นหาพนักงานด้วย Employee ID - ตรวจสอบ Hire Date / Employee Group / สถานะพนักงาน - ตรวจสอบ Special Benefit Group = Yes - ตรวจสอบข้อมูล Dependent / Emergency Contact และ Address ที่บันทึก | L4: EC - ระบบสร้าง Employee Record สำหรับ Hire Date > Today ได้ทันทีหลัง Submit โดยไม่ต้องรอถึง Hire Date - Hire Date = วันที่กรอก ซึ่งเป็นวันในอนาคต - Employee Group = A - Permanent - เมื่อ Copy Address from Employee = Yes ระบบใช้ข้อมูล Address ของ Employee และแสดงข้อความ “The address will be copied from the employee.” - เมื่อ Copy Address from Employee = No ระบบกำหนด Country / Province / District / Sub-District / Postal Code เป็น Required - ระบบแสดง Building / Floor / Village / Moo / Lane แต่ไม่กำหนดเป็น Required - พฤติกรรมเดียวกันทั้ง Dependent และ Emergency Contact - ระบบบันทึกข้อมูล Dependent / Emergency Contact ตามข้อมูลที่ระบุหลัง Submit สำเร็จ - ระบบบันทึก Special Benefit Group = Yes ได้ - Employee Status = Active ทันทีหลัง Submit แม้ Hire Date ยังไม่ถึง (Q&A ข้อ 32) | M4: Failed | N4: 46267 | O4: QA-Wannaphon | P4: #72008 | Q4: ตัดจากเคส E2E-03 ไฟล์ HR_SIT_E2E_V.0.1 (28).xlsx ชีท E2E All module โมดูลที่เคสเต็มเกี่ยวข้อง EC / TM / BE / PY / BE : Special Benefit Group = Yes ยกไปรอบเชื่อมโมดูล ผลที่คาดหวังฝั่ง Notification / TM / BE / PY ยกไปรอบเชื่อมโมดูล ขั้นตอน ตรวจสอบข้อมูลใน BE
A5: 4 | B5: Hiring | C5: E2E-04 | D5: Hiring | Keyin - Success | New Hire | Hire Date = Today | Age < 60 | Male | TH | A - Permanent | National ID Duplicate in Different BU | E5: HIR-EC-004 | F5: Positive | G5: High | H5: ตรวจสอบการจ้างพนักงานใหม่แบบ Key-in สำเร็จ กรณีวันเริ่มงานวันนี้ อายุ < 60 ปี เพศชาย สัญชาติไทย พนักงานประจำ และ National ID ซ้ำกับพนักงานต่าง BU | I5: - Entry Route = Keyin เงื่อนไขของเคสนี้ - Event Reason = New Hire - Hire Date = Today - Date of Birth = Age < 60 - Gender = Male - Nationality = Thai - National ID = ใช้ National ID ที่ซ้ำกับพนักงาน Active ที่มีอยู่แล้วใน Different BU และไม่ใช่กรณี Rehire - Thailand Format = N-NNNN-NNNNN-NN-N - Vietnam Format = NNNNNNNNN - Invalid National ID / Tax-ID = จำนวนหลักไม่ครบ - Employee Group = A - Permanent - DVT Project = null - Employee group = A - permanent - Special benefit group flag = No ค่าที่ต้องคีย์ ชุดข้อมูลจากถัง SIT ตรวจสอบเมื่อ 28 ส.ค. 2026 ชุดข้อมูล TD-01 - Business Group = CRC - Business Unit = CDG (10000075) Policy Profile = CDS - Company = C001 - Position = 40106337 Job Code = MKB12.12 - Department = 30042174 Branch = T153_1733 SSO Location = T153 - Division = 20000079 Cost Center = C00132653 Work Location = 50000127 - Work Schedule = D05H0830 Holiday Calendar = 01 - Personnel Grade (PG) = 10 Employee Sub Group ที่ต้องคีย์ = 10 - ตารางกำหนด Time Status = 01 O.T. Flag = yes สิทธิ์ลาพักผ่อนปีแรก = 6 วัน ชุดข้อมูล TD-42 - Business Unit = CFR (10000003) Policy Profile = CFR - Company = C004 - Position = 40007752 Job Code = STB10.12 - Department = 30002647 Branch = T224_1804 SSO Location = T224 - Division = 20001352 Cost Center = C00426100 Work Location = 50000183 - Work Schedule = D06H0800 Holiday Calendar = 03 - Personnel Grade (PG) = 10 Employee Sub Group ที่ต้องคีย์ = 10 เงื่อนไขเฉพาะของเคสนี้ - รอบที่ 1 ใช้ TD-01 Business Unit CDG รอบที่ 2 ใช้ TD-42 Business Unit CFR ด้วยเลขบัตรประชาชนเดียวกัน - รายละเอียดเต็มดูชีท Hiring Test Data หมายเหตุ - ดราฟต์เดิมระบุ Personnel Grade (PG) = 15 ใช้ 10 / 10 ตามชุดข้อมูลจริงในถัง SIT | J5: EC > Hire & Onboard (New Hire) | K5: 1. Login ด้วย <HR_ADMIN_ACCOUNT> - ไปที่ EC > New Hire (Manual Key-in) 2. ตรวจสอบ Duplicate National ID / Tax-ID - กรอก National ID ที่ซ้ำกับพนักงาน Active ที่มีอยู่แล้วใน Different BU และไม่ใช่กรณี Rehire - ตรวจสอบว่าระหว่างกรอก ระบบยังไม่ Validate Duplicate แบบ Real-time 3. ตรวจสอบ Invalid Format ก่อน Duplicate Check - กรอก National ID / Tax-ID ที่จำนวนหลักไม่ครบ - กรอกข้อมูล Mandatory อื่นให้ครบถ้วนเพื่อให้สามารถ Submit ได้ - กด Submit - ตรวจสอบผล Validation - ตรวจสอบว่าระบบ Reject ก่อนเข้าสู่ขั้นตอนตรวจ Duplicate 4. ตรวจสอบ Duplicate ด้วย National ID ที่ Format ถูกต้อง - กรอก National ID ประเทศไทยในรูปแบบ N-NNNN-NNNNN-NN-N โดยใช้ค่าที่ซ้ำกับพนักงาน Active ใน Different BU - กรณีตรวจสอบ Vietnam ให้ใช้รูปแบบ NNNNNNNNN - กำหนด Employee Group = A - Permanent - กรอกข้อมูล Mandatory อื่นให้ครบถ้วนเพื่อให้สามารถ Submit ได้ 5. กด Submit - ตรวจสอบว่าระบบตรวจพบ National ID ซ้ำกับพนักงานที่มีอยู่แล้วใน Different BU - ตรวจสอบ Notice ที่ระบบแสดง - บันทึกข้อความ Notice ที่พบจริง - บันทึกว่าหลังพบ Duplicate ระบบอนุญาตให้ Submit ต่อหรือ Block การ Submit | L5: EC - ระบบตรวจสอบ Duplicate National ID / Tax-ID ตอนกด Submit เท่านั้น และไม่ Validate Duplicate แบบ Real-time ขณะกรอกข้อมูล - ระบบตรวจพบว่า National ID ซ้ำกับพนักงาน Active ที่มีอยู่แล้ว แม้พนักงานเดิมจะอยู่คนละ Business Unit - ระบบแสดง Notice แจ้งว่า National ID / Tax-ID ซ้ำหรือมีอยู่แล้ว - National ID / Tax-ID Format - ระบบรองรับรูปแบบ Thailand = N-NNNN-NNNNN-NN-N - ระบบรองรับรูปแบบ Vietnam = NNNNNNNNN - กรณี National ID / Tax-ID ผิดรูปแบบหรือจำนวนหลักไม่ครบ ระบบ Reject ก่อนเข้าสู่ขั้นตอนตรวจ Duplicate - ข้อความ Notice ที่แน่นอน = ? OQ-HIR-140 - พฤติกรรมหลังพบ Duplicate ว่าระบบอนุญาตให้ Submit ต่อหรือ Block การ Submit = ? OQ-HIR-140 จุดที่ยังไม่มีคำตอบในเคสนี้ ให้รันจริงแล้วบันทึกค่าที่ระบบแสดงลงช่อง Actual Result Image และช่อง Note เพื่อใช้เป็นคำตอบ แล้วส่งให้ BA หรือ SA ยืนยัน หมายเลขคำถามที่ต้องเก็บคำตอบระหว่างรัน OQ-HIR-140 | M5: Cancelled | Q5: ซ้ำกับ 028 ระบุเองว่าเป็นคำตอบทางการของข้อค้างใน E2E-04
A6: 5 | B6: Hiring | C6: E2E-05 | D6: Hiring | Keyin - Success | New Hire | Hire Date = Today | Age < 60 | Female | Non TH | A - Permanent | E6: HIR-EC-005 | F6: Positive | G6: High | H6: ตรวจสอบการจ้างพนักงานใหม่แบบ Key-in สำเร็จ กรณีวันเริ่มงานวันนี้ อายุ < 60 ปี เพศหญิง สัญชาติ Non-TH และเป็นพนักงานประจำ | I6: - Entry Route = Keyin เงื่อนไขของเคสนี้ - Event Reason = New Hire - Hire Date = Today - Date of Birth = Age < 60 - Gender = Female - Nationality / Country = Non-TH และ Non-VN - Passport Number = AB1234567 - Passport Issue Date = 01/02/2021 - Passport Expiry Date = < Current Date - Tax ID = 1234567890123 - Document Type = ? รอตารางค่าจริง - Country = Japan - Document Number = WP2026000123 - Issue Date = 01/03/2025 - Expiry Date = 28/02/2026 - Arrival Date (VISA) = 01/03/2025 - 90-days Report (VISA) = 30/05/2025 - Employee Group = A - Permanent - DVT Project = null - Employee group = A - permanent - Special benefit group flag = No ค่าที่ต้องคีย์ ชุดข้อมูลจากถัง SIT ตรวจสอบเมื่อ 28 ส.ค. 2026 ชุดข้อมูล TD-01 - Business Group = CRC - Business Unit = CDG (10000075) Policy Profile = CDS - Company = C001 - Position = 40106337 Job Code = MKB12.12 - Department = 30042174 Branch = T153_1733 SSO Location = T153 - Division = 20000079 Cost Center = C00132653 Work Location = 50000127 - Work Schedule = D05H0830 Holiday Calendar = 01 - Personnel Grade (PG) = 10 Employee Sub Group ที่ต้องคีย์ = 10 - ตารางกำหนด Time Status = 01 O.T. Flag = yes สิทธิ์ลาพักผ่อนปีแรก = 6 วัน เงื่อนไขเฉพาะของเคสนี้ - Nationality = Non-TH และ Non-VN - รายละเอียดเต็มดูชีท Hiring Test Data หมายเหตุ - ดราฟต์เดิมระบุ Business Unit = CDS ใช้ CDG ตามชุดข้อมูลจริงในถัง SIT CDS ปิดใช้งานตั้งแต่ 1 ต.ค. 2024 ตามไฟล์ FO และไม่มี Position ในถัง SIT | J6: EC > Hire & Onboard (New Hire) | K6: 1. Login ด้วย <HR_ADMIN_ACCOUNT> - ไปที่ EC > New Hire (Manual Key-in) 2. กรอกข้อมูล Identity สำหรับพนักงานต่างชาติ - กำหนด Nationality / Country = Non-TH และ Non-VN - กรอก Passport Number - ตรวจสอบว่า Passport Issue Date และ Passport Expiry Date เป็น Required - กรอก Passport Issue Date และ Passport Expiry Date ตาม Test Data - กรอก Passport / Tax ID แทน National ID 13 หลัก 3. ตรวจสอบ Passport หมดอายุ - กำหนด Passport Expiry Date < Current Date - ตรวจสอบข้อความ “Passport has expired” 4. เพิ่มข้อมูล Work Permit - กรอก Document Type / Country / Document Number / Issue Date / Expiry Date / Arrival Date (VISA) / 90-days Report (VISA) - เพิ่ม Work Permit มากกว่า 1 รายการ - ตรวจสอบว่าระบบรองรับการเพิ่มหลายรายการ 5. กรอกข้อมูลการจ้างงานที่จำเป็น - กำหนด Employee Group = A - Permanent - กรอกข้อมูล Mandatory อื่นให้ครบถ้วนเพื่อให้สามารถ Submit ได้ 6. กด Submit เพื่อสร้างพนักงานใหม่ 7. ตรวจสอบ Employee Profile ใน EC - ค้นหาพนักงานที่สร้างใหม่ด้วย Employee ID - ตรวจสอบ Nationality / Passport / Tax ID - ตรวจสอบข้อมูล Work Permit ทุกรายการ - ตรวจสอบ Arrival Date (VISA) / 90-days Report (VISA) - ตรวจสอบ Employee Group | L6: EC - ระบบรองรับการสร้างพนักงาน Nationality = Non TH - Employee Group = A - Permanent - ระบบให้กรอก Work Permit หรือ Passport แทน National ID 13 หลักได้ - ระบบบันทึก Passport Number / Tax ID / Work Permit ตามข้อมูลที่กรอก - เมื่อกรอก Passport Number ระบบกำหนด Passport Issue Date และ Passport Expiry Date เป็น Required - เมื่อ Passport Expiry Date < Current Date ระบบแสดงข้อความ “Passport has expired” - ระบบรองรับการเพิ่ม Work Permit มากกว่า 1 รายการต่อพนักงาน 1 คน - ระบบบันทึก Document Type / Country / Document Number / Issue Date / Expiry Date / Arrival Date (VISA) / 90-days Report (VISA) ได้ - 90-days Report (VISA) ยังไม่มี Business Rule เพิ่มเติม จึงตรวจเฉพาะว่าสามารถบันทึกค่าตามที่ระบุได้ - พฤติกรรมกรณี Passport หมดอายุว่าเป็น Warning และยัง Submit ได้ หรือ Block การ Submit = ? OQ-HIR-61 - ตารางค่าของ Document Type = ? OQ-HIR-78 - Country ใน Work Permit = Thailand (Q&A ข้อ 33) จุดที่ยังไม่มีคำตอบในเคสนี้ ให้รันจริงแล้วบันทึกค่าที่ระบบแสดงลงช่อง Actual Result Image และช่อง Note เพื่อใช้เป็นคำตอบ แล้วส่งให้ BA หรือ SA ยืนยัน หมายเลขคำถามที่ต้องเก็บคำตอบระหว่างรัน OQ-HIR-61, OQ-HIR-78 | M6: Failed | N6: 46267 | O6: QA-Wannaphon | P6: #72050 | Q6: ตัดจากเคส E2E-05 ไฟล์ HR_SIT_E2E_V.0.1 (28).xlsx ชีท E2E All module โมดูลที่เคสเต็มเกี่ยวข้อง EC / BE / TM / PY / Notification ยกไปรอบเชื่อมโมดูล ผลที่คาดหวังฝั่ง Notification / TM / BE / PY ยกไปรอบเชื่อมโมดูล ขั้นตอน ตรวจสอบผลใน PY เคสนี้มีจุดที่ยังไม่มีคำตอบ 2 จุด ไม่ต้องรอคำตอบก่อนรัน ให้รันเก็บค่าที่ระบบแสดงจริงแล้วแจ้ง BA หรือ SA ยืนยันหลังรัน
